2024-05-02 15:29:05,579 ERROR Internal Server Error: /create_article/ C:\Users\igor_\Desktop\skillfactory\Module D\NewsPaper\venv\Lib\site-packages\django\utils\log.py (<class 'django.db.utils.IntegrityError'>, IntegrityError('NOT NULL constraint failed: news_post.author_id'), <traceback object at 0x00000278FCFB9C80>)
Traceback (most recent call last):
  File "C:\Users\igor_\Desktop\skillfactory\Module D\NewsPaper\venv\Lib\site-packages\django\db\backends\utils.py", line 105, in _execute
    return self.cursor.execute(sql, params)
           ^^^^^^^^^^^^^^^^^^^^^^^^^^^^^^^^
  File "C:\Users\igor_\Desktop\skillfactory\Module D\NewsPaper\venv\Lib\site-packages\django\db\backends\sqlite3\base.py", line 328, in execute
    return super().execute(query, params)
           ^^^^^^^^^^^^^^^^^^^^^^^^^^^^^^
sqlite3.IntegrityError: NOT NULL constraint failed: news_post.author_id

The above exception was the direct cause of the following exception:

Traceback (most recent call last):
  File "C:\Users\igor_\Desktop\skillfactory\Module D\NewsPaper\venv\Lib\site-packages\django\core\handlers\exception.py", line 55, in inner
    response = get_response(request)
               ^^^^^^^^^^^^^^^^^^^^^
  File "C:\Users\igor_\Desktop\skillfactory\Module D\NewsPaper\venv\Lib\site-packages\django\core\handlers\base.py", line 197, in _get_response
    response = wrapped_callback(request, *callback_args, **callback_kwargs)
               ^^^^^^^^^^^^^^^^^^^^^^^^^^^^^^^^^^^^^^^^^^^^^^^^^^^^^^^^^^^^
  File "C:\Users\igor_\Desktop\skillfactory\Module D\NewsPaper\NewsPaper\news\views.py", line 251, in create_article
    article = Post.objects.create(
              ^^^^^^^^^^^^^^^^^^^^
  File "C:\Users\igor_\Desktop\skillfactory\Module D\NewsPaper\venv\Lib\site-packages\django\db\models\manager.py", line 87, in manager_method
    return getattr(self.get_queryset(), name)(*args, **kwargs)
           ^^^^^^^^^^^^^^^^^^^^^^^^^^^^^^^^^^^^^^^^^^^^^^^^^^^
  File "C:\Users\igor_\Desktop\skillfactory\Module D\NewsPaper\venv\Lib\site-packages\modeltranslation\manager.py", line 411, in create
    return super().create(**kwargs)
           ^^^^^^^^^^^^^^^^^^^^^^^^
  File "C:\Users\igor_\Desktop\skillfactory\Module D\NewsPaper\venv\Lib\site-packages\django\db\models\query.py", line 677, in create
    obj.save(force_insert=True, using=self.db)
  File "C:\Users\igor_\Desktop\skillfactory\Module D\NewsPaper\NewsPaper\news\models.py", line 80, in save
    super().save(*args, **kwargs)   # сначала вызываем метод родителя, чтобы объект сохранился
    ^^^^^^^^^^^^^^^^^^^^^^^^^^^^^
  File "C:\Users\igor_\Desktop\skillfactory\Module D\NewsPaper\venv\Lib\site-packages\django\db\models\base.py", line 822, in save
    self.save_base(
  File "C:\Users\igor_\Desktop\skillfactory\Module D\NewsPaper\venv\Lib\site-packages\django\db\models\base.py", line 909, in save_base
    updated = self._save_table(
              ^^^^^^^^^^^^^^^^^
  File "C:\Users\igor_\Desktop\skillfactory\Module D\NewsPaper\venv\Lib\site-packages\django\db\models\base.py", line 1067, in _save_table
    results = self._do_insert(
              ^^^^^^^^^^^^^^^^
  File "C:\Users\igor_\Desktop\skillfactory\Module D\NewsPaper\venv\Lib\site-packages\django\db\models\base.py", line 1108, in _do_insert
    return manager._insert(
           ^^^^^^^^^^^^^^^^
  File "C:\Users\igor_\Desktop\skillfactory\Module D\NewsPaper\venv\Lib\site-packages\django\db\models\manager.py", line 87, in manager_method
    return getattr(self.get_queryset(), name)(*args, **kwargs)
           ^^^^^^^^^^^^^^^^^^^^^^^^^^^^^^^^^^^^^^^^^^^^^^^^^^^
  File "C:\Users\igor_\Desktop\skillfactory\Module D\NewsPaper\venv\Lib\site-packages\django\db\models\query.py", line 1845, in _insert
    return query.get_compiler(using=using).execute_sql(returning_fields)
           ^^^^^^^^^^^^^^^^^^^^^^^^^^^^^^^^^^^^^^^^^^^^^^^^^^^^^^^^^^^^^
  File "C:\Users\igor_\Desktop\skillfactory\Module D\NewsPaper\venv\Lib\site-packages\django\db\models\sql\compiler.py", line 1823, in execute_sql
    cursor.execute(sql, params)
  File "C:\Users\igor_\Desktop\skillfactory\Module D\NewsPaper\venv\Lib\site-packages\django\db\backends\utils.py", line 122, in execute
    return super().execute(sql, params)
           ^^^^^^^^^^^^^^^^^^^^^^^^^^^^
  File "C:\Users\igor_\Desktop\skillfactory\Module D\NewsPaper\venv\Lib\site-packages\django\db\backends\utils.py", line 79, in execute
    return self._execute_with_wrappers(
           ^^^^^^^^^^^^^^^^^^^^^^^^^^^^
  File "C:\Users\igor_\Desktop\skillfactory\Module D\NewsPaper\venv\Lib\site-packages\django\db\backends\utils.py", line 92, in _execute_with_wrappers
    return executor(sql, params, many, context)
           ^^^^^^^^^^^^^^^^^^^^^^^^^^^^^^^^^^^^
  File "C:\Users\igor_\Desktop\skillfactory\Module D\NewsPaper\venv\Lib\site-packages\django\db\backends\utils.py", line 100, in _execute
    with self.db.wrap_database_errors:
  File "C:\Users\igor_\Desktop\skillfactory\Module D\NewsPaper\venv\Lib\site-packages\django\db\utils.py", line 91, in __exit__
    raise dj_exc_value.with_traceback(traceback) from exc_value
  File "C:\Users\igor_\Desktop\skillfactory\Module D\NewsPaper\venv\Lib\site-packages\django\db\backends\utils.py", line 105, in _execute
    return self.cursor.execute(sql, params)
           ^^^^^^^^^^^^^^^^^^^^^^^^^^^^^^^^
  File "C:\Users\igor_\Desktop\skillfactory\Module D\NewsPaper\venv\Lib\site-packages\django\db\backends\sqlite3\base.py", line 328, in execute
    return super().execute(query, params)
           ^^^^^^^^^^^^^^^^^^^^^^^^^^^^^^
django.db.utils.IntegrityError: NOT NULL constraint failed: news_post.author_id
2024-05-02 15:29:05,658 ERROR "GET /create_article/ HTTP/1.1" 500 181652 C:\Users\igor_\Desktop\skillfactory\Module D\NewsPaper\venv\Lib\site-packages\django\core\servers\basehttp.py None
2024-05-02 15:32:28,693 ERROR Internal Server Error: /edit_article/137/ C:\Users\igor_\Desktop\skillfactory\Module D\NewsPaper\venv\Lib\site-packages\django\utils\log.py (<class 'json.decoder.JSONDecodeError'>, JSONDecodeError('Expecting value: line 1 column 1 (char 0)'), <traceback object at 0x00000278FD193600>)
Traceback (most recent call last):
  File "C:\Users\igor_\Desktop\skillfactory\Module D\NewsPaper\venv\Lib\site-packages\django\core\handlers\exception.py", line 55, in inner
    response = get_response(request)
               ^^^^^^^^^^^^^^^^^^^^^
  File "C:\Users\igor_\Desktop\skillfactory\Module D\NewsPaper\venv\Lib\site-packages\django\core\handlers\base.py", line 197, in _get_response
    response = wrapped_callback(request, *callback_args, **callback_kwargs)
               ^^^^^^^^^^^^^^^^^^^^^^^^^^^^^^^^^^^^^^^^^^^^^^^^^^^^^^^^^^^^
  File "C:\Users\igor_\Desktop\skillfactory\Module D\NewsPaper\NewsPaper\news\views.py", line 259, in edit_article
    body = json.loads(request.body.decode('utf-8'))
           ^^^^^^^^^^^^^^^^^^^^^^^^^^^^^^^^^^^^^^^^
  File "C:\Program Files\Python312\Lib\json\__init__.py", line 346, in loads
    return _default_decoder.decode(s)
           ^^^^^^^^^^^^^^^^^^^^^^^^^^
  File "C:\Program Files\Python312\Lib\json\decoder.py", line 337, in decode
    obj, end = self.raw_decode(s, idx=_w(s, 0).end())
               ^^^^^^^^^^^^^^^^^^^^^^^^^^^^^^^^^^^^^^
  File "C:\Program Files\Python312\Lib\json\decoder.py", line 355, in raw_decode
    raise JSONDecodeError("Expecting value", s, err.value) from None
json.decoder.JSONDecodeError: Expecting value: line 1 column 1 (char 0)
2024-05-02 15:32:28,765 ERROR "GET /edit_article/137/ HTTP/1.1" 500 83432 C:\Users\igor_\Desktop\skillfactory\Module D\NewsPaper\venv\Lib\site-packages\django\core\servers\basehttp.py None
2024-05-02 15:32:42,279 ERROR Internal Server Error: /edit_article/107/ C:\Users\igor_\Desktop\skillfactory\Module D\NewsPaper\venv\Lib\site-packages\django\utils\log.py (<class 'json.decoder.JSONDecodeError'>, JSONDecodeError('Expecting value: line 1 column 1 (char 0)'), <traceback object at 0x00000278FCDFCBC0>)
Traceback (most recent call last):
  File "C:\Users\igor_\Desktop\skillfactory\Module D\NewsPaper\venv\Lib\site-packages\django\core\handlers\exception.py", line 55, in inner
    response = get_response(request)
               ^^^^^^^^^^^^^^^^^^^^^
  File "C:\Users\igor_\Desktop\skillfactory\Module D\NewsPaper\venv\Lib\site-packages\django\core\handlers\base.py", line 197, in _get_response
    response = wrapped_callback(request, *callback_args, **callback_kwargs)
               ^^^^^^^^^^^^^^^^^^^^^^^^^^^^^^^^^^^^^^^^^^^^^^^^^^^^^^^^^^^^
  File "C:\Users\igor_\Desktop\skillfactory\Module D\NewsPaper\NewsPaper\news\views.py", line 259, in edit_article
    body = json.loads(request.body.decode('utf-8'))
           ^^^^^^^^^^^^^^^^^^^^^^^^^^^^^^^^^^^^^^^^
  File "C:\Program Files\Python312\Lib\json\__init__.py", line 346, in loads
    return _default_decoder.decode(s)
           ^^^^^^^^^^^^^^^^^^^^^^^^^^
  File "C:\Program Files\Python312\Lib\json\decoder.py", line 337, in decode
    obj, end = self.raw_decode(s, idx=_w(s, 0).end())
               ^^^^^^^^^^^^^^^^^^^^^^^^^^^^^^^^^^^^^^
  File "C:\Program Files\Python312\Lib\json\decoder.py", line 355, in raw_decode
    raise JSONDecodeError("Expecting value", s, err.value) from None
json.decoder.JSONDecodeError: Expecting value: line 1 column 1 (char 0)
2024-05-02 15:32:42,293 ERROR "GET /edit_article/107/ HTTP/1.1" 500 83432 C:\Users\igor_\Desktop\skillfactory\Module D\NewsPaper\venv\Lib\site-packages\django\core\servers\basehttp.py None
2024-05-02 15:33:16,396 ERROR Internal Server Error: /edit_article/113/ C:\Users\igor_\Desktop\skillfactory\Module D\NewsPaper\venv\Lib\site-packages\django\utils\log.py (<class 'json.decoder.JSONDecodeError'>, JSONDecodeError('Expecting value: line 1 column 1 (char 0)'), <traceback object at 0x00000278FD098280>)
Traceback (most recent call last):
  File "C:\Users\igor_\Desktop\skillfactory\Module D\NewsPaper\venv\Lib\site-packages\django\core\handlers\exception.py", line 55, in inner
    response = get_response(request)
               ^^^^^^^^^^^^^^^^^^^^^
  File "C:\Users\igor_\Desktop\skillfactory\Module D\NewsPaper\venv\Lib\site-packages\django\core\handlers\base.py", line 197, in _get_response
    response = wrapped_callback(request, *callback_args, **callback_kwargs)
               ^^^^^^^^^^^^^^^^^^^^^^^^^^^^^^^^^^^^^^^^^^^^^^^^^^^^^^^^^^^^
  File "C:\Users\igor_\Desktop\skillfactory\Module D\NewsPaper\NewsPaper\news\views.py", line 259, in edit_article
    body = json.loads(request.body.decode('utf-8'))
           ^^^^^^^^^^^^^^^^^^^^^^^^^^^^^^^^^^^^^^^^
  File "C:\Program Files\Python312\Lib\json\__init__.py", line 346, in loads
    return _default_decoder.decode(s)
           ^^^^^^^^^^^^^^^^^^^^^^^^^^
  File "C:\Program Files\Python312\Lib\json\decoder.py", line 337, in decode
    obj, end = self.raw_decode(s, idx=_w(s, 0).end())
               ^^^^^^^^^^^^^^^^^^^^^^^^^^^^^^^^^^^^^^
  File "C:\Program Files\Python312\Lib\json\decoder.py", line 355, in raw_decode
    raise JSONDecodeError("Expecting value", s, err.value) from None
json.decoder.JSONDecodeError: Expecting value: line 1 column 1 (char 0)
2024-05-02 15:33:16,416 ERROR "GET /edit_article/113/ HTTP/1.1" 500 83432 C:\Users\igor_\Desktop\skillfactory\Module D\NewsPaper\venv\Lib\site-packages\django\core\servers\basehttp.py None
2024-05-02 15:34:14,115 ERROR Internal Server Error: /edit_article/113/ C:\Users\igor_\Desktop\skillfactory\Module D\NewsPaper\venv\Lib\site-packages\django\utils\log.py (<class 'json.decoder.JSONDecodeError'>, JSONDecodeError('Expecting value: line 1 column 1 (char 0)'), <traceback object at 0x00000278FCF36980>)
Traceback (most recent call last):
  File "C:\Users\igor_\Desktop\skillfactory\Module D\NewsPaper\venv\Lib\site-packages\django\core\handlers\exception.py", line 55, in inner
    response = get_response(request)
               ^^^^^^^^^^^^^^^^^^^^^
  File "C:\Users\igor_\Desktop\skillfactory\Module D\NewsPaper\venv\Lib\site-packages\django\core\handlers\base.py", line 197, in _get_response
    response = wrapped_callback(request, *callback_args, **callback_kwargs)
               ^^^^^^^^^^^^^^^^^^^^^^^^^^^^^^^^^^^^^^^^^^^^^^^^^^^^^^^^^^^^
  File "C:\Users\igor_\Desktop\skillfactory\Module D\NewsPaper\NewsPaper\news\views.py", line 259, in edit_article
    body = json.loads(request.body.decode('utf-8'))
           ^^^^^^^^^^^^^^^^^^^^^^^^^^^^^^^^^^^^^^^^
  File "C:\Program Files\Python312\Lib\json\__init__.py", line 346, in loads
    return _default_decoder.decode(s)
           ^^^^^^^^^^^^^^^^^^^^^^^^^^
  File "C:\Program Files\Python312\Lib\json\decoder.py", line 337, in decode
    obj, end = self.raw_decode(s, idx=_w(s, 0).end())
               ^^^^^^^^^^^^^^^^^^^^^^^^^^^^^^^^^^^^^^
  File "C:\Program Files\Python312\Lib\json\decoder.py", line 355, in raw_decode
    raise JSONDecodeError("Expecting value", s, err.value) from None
json.decoder.JSONDecodeError: Expecting value: line 1 column 1 (char 0)
2024-05-02 15:34:14,128 ERROR "GET /edit_article/113/ HTTP/1.1" 500 83432 C:\Users\igor_\Desktop\skillfactory\Module D\NewsPaper\venv\Lib\site-packages\django\core\servers\basehttp.py None
2024-05-02 15:36:19,713 ERROR Internal Server Error: /edit_article/113/ C:\Users\igor_\Desktop\skillfactory\Module D\NewsPaper\venv\Lib\site-packages\django\utils\log.py (<class 'json.decoder.JSONDecodeError'>, JSONDecodeError('Expecting value: line 1 column 1 (char 0)'), <traceback object at 0x00000278FD2CAD80>)
Traceback (most recent call last):
  File "C:\Users\igor_\Desktop\skillfactory\Module D\NewsPaper\venv\Lib\site-packages\django\core\handlers\exception.py", line 55, in inner
    response = get_response(request)
               ^^^^^^^^^^^^^^^^^^^^^
  File "C:\Users\igor_\Desktop\skillfactory\Module D\NewsPaper\venv\Lib\site-packages\django\core\handlers\base.py", line 197, in _get_response
    response = wrapped_callback(request, *callback_args, **callback_kwargs)
               ^^^^^^^^^^^^^^^^^^^^^^^^^^^^^^^^^^^^^^^^^^^^^^^^^^^^^^^^^^^^
  File "C:\Users\igor_\Desktop\skillfactory\Module D\NewsPaper\NewsPaper\news\views.py", line 259, in edit_article
    body = json.loads(request.body.decode('utf-8'))
           ^^^^^^^^^^^^^^^^^^^^^^^^^^^^^^^^^^^^^^^^
  File "C:\Program Files\Python312\Lib\json\__init__.py", line 346, in loads
    return _default_decoder.decode(s)
           ^^^^^^^^^^^^^^^^^^^^^^^^^^
  File "C:\Program Files\Python312\Lib\json\decoder.py", line 337, in decode
    obj, end = self.raw_decode(s, idx=_w(s, 0).end())
               ^^^^^^^^^^^^^^^^^^^^^^^^^^^^^^^^^^^^^^
  File "C:\Program Files\Python312\Lib\json\decoder.py", line 355, in raw_decode
    raise JSONDecodeError("Expecting value", s, err.value) from None
json.decoder.JSONDecodeError: Expecting value: line 1 column 1 (char 0)
2024-05-02 15:36:19,739 ERROR "GET /edit_article/113/ HTTP/1.1" 500 83432 C:\Users\igor_\Desktop\skillfactory\Module D\NewsPaper\venv\Lib\site-packages\django\core\servers\basehttp.py None
2024-05-02 18:48:04,337 ERROR Internal Server Error: /create_article/ C:\Users\igor_\Desktop\skillfactory\Module D\NewsPaper\venv\Lib\site-packages\django\utils\log.py (<class 'json.decoder.JSONDecodeError'>, JSONDecodeError('Expecting value: line 1 column 1 (char 0)'), <traceback object at 0x000002725F4C2140>)
Traceback (most recent call last):
  File "C:\Users\igor_\Desktop\skillfactory\Module D\NewsPaper\venv\Lib\site-packages\django\core\handlers\exception.py", line 55, in inner
    response = get_response(request)
               ^^^^^^^^^^^^^^^^^^^^^
  File "C:\Users\igor_\Desktop\skillfactory\Module D\NewsPaper\venv\Lib\site-packages\django\core\handlers\base.py", line 197, in _get_response
    response = wrapped_callback(request, *callback_args, **callback_kwargs)
               ^^^^^^^^^^^^^^^^^^^^^^^^^^^^^^^^^^^^^^^^^^^^^^^^^^^^^^^^^^^^
  File "C:\Users\igor_\Desktop\skillfactory\Module D\NewsPaper\NewsPaper\news\views.py", line 250, in create_article
    body = json.loads(request.body.decode('utf-8'))
           ^^^^^^^^^^^^^^^^^^^^^^^^^^^^^^^^^^^^^^^^
  File "C:\Program Files\Python312\Lib\json\__init__.py", line 346, in loads
    return _default_decoder.decode(s)
           ^^^^^^^^^^^^^^^^^^^^^^^^^^
  File "C:\Program Files\Python312\Lib\json\decoder.py", line 337, in decode
    obj, end = self.raw_decode(s, idx=_w(s, 0).end())
               ^^^^^^^^^^^^^^^^^^^^^^^^^^^^^^^^^^^^^^
  File "C:\Program Files\Python312\Lib\json\decoder.py", line 355, in raw_decode
    raise JSONDecodeError("Expecting value", s, err.value) from None
json.decoder.JSONDecodeError: Expecting value: line 1 column 1 (char 0)
2024-05-02 18:48:04,370 ERROR "GET /create_article/ HTTP/1.1" 500 81369 C:\Users\igor_\Desktop\skillfactory\Module D\NewsPaper\venv\Lib\site-packages\django\core\servers\basehttp.py None
2024-05-02 18:55:10,773 ERROR Internal Server Error: /create_article/ C:\Users\igor_\Desktop\skillfactory\Module D\NewsPaper\venv\Lib\site-packages\django\utils\log.py (<class 'json.decoder.JSONDecodeError'>, JSONDecodeError('Expecting value: line 1 column 1 (char 0)'), <traceback object at 0x000002725F49DA80>)
Traceback (most recent call last):
  File "C:\Users\igor_\Desktop\skillfactory\Module D\NewsPaper\venv\Lib\site-packages\django\core\handlers\exception.py", line 55, in inner
    response = get_response(request)
               ^^^^^^^^^^^^^^^^^^^^^
  File "C:\Users\igor_\Desktop\skillfactory\Module D\NewsPaper\venv\Lib\site-packages\django\core\handlers\base.py", line 197, in _get_response
    response = wrapped_callback(request, *callback_args, **callback_kwargs)
               ^^^^^^^^^^^^^^^^^^^^^^^^^^^^^^^^^^^^^^^^^^^^^^^^^^^^^^^^^^^^
  File "C:\Users\igor_\Desktop\skillfactory\Module D\NewsPaper\NewsPaper\news\views.py", line 250, in create_article
    body = json.loads(request.body.decode('utf-8'))
           ^^^^^^^^^^^^^^^^^^^^^^^^^^^^^^^^^^^^^^^^
  File "C:\Program Files\Python312\Lib\json\__init__.py", line 346, in loads
    return _default_decoder.decode(s)
           ^^^^^^^^^^^^^^^^^^^^^^^^^^
  File "C:\Program Files\Python312\Lib\json\decoder.py", line 337, in decode
    obj, end = self.raw_decode(s, idx=_w(s, 0).end())
               ^^^^^^^^^^^^^^^^^^^^^^^^^^^^^^^^^^^^^^
  File "C:\Program Files\Python312\Lib\json\decoder.py", line 355, in raw_decode
    raise JSONDecodeError("Expecting value", s, err.value) from None
json.decoder.JSONDecodeError: Expecting value: line 1 column 1 (char 0)
2024-05-02 18:55:10,801 ERROR "GET /create_article/ HTTP/1.1" 500 81369 C:\Users\igor_\Desktop\skillfactory\Module D\NewsPaper\venv\Lib\site-packages\django\core\servers\basehttp.py None
